Workbook

Sheet Weekly Report
A1: Weekly Team Activity Report
A2: Week of 2026-08-10 to 2026-08-14 | Author names withheld, shown as User 1-7 | Weekends excluded
A4: Monday, 2026-08-10 | Team Availability: 7/7 | New Tickets Created: 3
A5: Ticket Key | B5: Summary | C5: Authors on Ticket | D5: Hours Logged | E5: Priority | F5: Status
A6: CWL-2916 | B6: Ad hoc: August | C6: =SUMIFS(Data!$H:$H,Data!$A:$A,DATE(2026,8,10),Data!$B:$B,"CWL-2916") -> 7 | D6: =ROUND(SUMIFS(Data!$D:$D,Data!$A:$A,DATE(2026,8,10),Data!$B:$B,"CWL-2916"),2) -> 7.5 | E6: Low | F6: TICKET ACKNOWLEDGEMENT
A7: CWL-2890 | B7: 2026_S3_LC Virto Charger Go - Web page updates | C7: =SUMIFS(Data!$H:$H,Data!$A:$A,DATE(2026,8,10),Data!$B:$B,"CWL-2890") -> 2 | D7: =ROUND(SUMIFS(Data!$D:$D,Data!$A:$A,DATE(2026,8,10),Data!$B:$B,"CWL-2890"),2) -> 0.75 | E7: Medium | F7: DONE
A8: CWL-2869 | B8: HT_Website_PhaseoutUpdate-June26 | C8: =SUMIFS(Data!$H:$H,Data!$A:$A,DATE(2026,8,10),Data!$B:$B,"CWL-2869") -> 3 | D8: =ROUND(SUMIFS(Data!$D:$D,Data!$A:$A,DATE(2026,8,10),Data!$B:$B,"CWL-2869"),2) -> 5.5 | E8: Medium | F8: DONE
A9: CWL-2464 | B9: Move Phonak Hearing Stories to new Blog Component | C9: =SUMIFS(Data!$H:$H,Data!$A:$A,DATE(2026,8,10),Data!$B:$B,"CWL-2464") -> 5 | D9: =ROUND(SUMIFS(Data!$D:$D,Data!$A:$A,DATE(2026,8,10),Data!$B:$B,"CWL-2464"),2) -> 22.77 | E9: Low | F9: IN PROGRESS
A10: CWL-2920 | B10: HT_Website_France-S3-2026 Update | C10: =SUMIFS(Data!$H:$H,Data!$A:$A,DATE(2026,8,10),Data!$B:$B,"CWL-2920") -> 1 | D10: =ROUND(SUMIFS(Data!$D:$D,Data!$A:$A,DATE(2026,8,10),Data!$B:$B,"CWL-2920"),2) -> 4 | E10: Medium | F10: WAITING FOR APPROVAL (MIGRATED)
A11: CWL-2919 | B11: HT_Website_International_PL-Userguide-Upload | C11: =SUMIFS(Data!$H:$H,Data!$A:$A,DATE(2026,8,10),Data!$B:$B,"CWL-2919") -> 1 | D11: =ROUND(SUMIFS(Data!$D:$D,Data!$A:$A,DATE(2026,8,10),Data!$B:$B,"CWL-2919"),2) -> 0.5 | E11: Medium | F11: DONE
A12: ="Day Total ("&COUNTA(A6:A11)&" tickets)" -> Day Total (6 tickets) | D12: =ROUND(SUM(D6:D11),2) -> 41.02
A14: Tuesday, 2026-08-11 | Team Availability: 7/7 | New Tickets Created: 0
A15: Ticket Key | B15: Summary | C15: Authors on Ticket | D15: Hours Logged | E15: Priority | F15: Status
A16: CWL-2921 | B16: Create a new "Conditions Générales de Vente" page for each webiste brand and add a footer link on the French Phonak, Unitron and Hansaton websites | C16: =SUMIFS(Data!$H:$H,Data!$A:$A,DATE(2026,8,11),Data!$B:$B,"CWL-2921") -> 1 | D16: =ROUND(SUMIFS(Data!$D:$D,Data!$A:$A,DATE(2026,8,11),Data!$B:$B,"CWL-2921"),2) -> 6 | E16: Medium | F16: APPROVED FOR ACTIVATION
A17: CWL-2916 | B17: Ad hoc: August | C17: =SUMIFS(Data!$H:$H,Data!$A:$A,DATE(2026,8,11),Data!$B:$B,"CWL-2916") -> 7 | D17: =ROUND(SUMIFS(Data!$D:$D,Data!$A:$A,DATE(2026,8,11),Data!$B:$B,"CWL-2916"),2) -> 7.5 | E17: Low | F17: TICKET ACKNOWLEDGEMENT
A18: CWL-2922 | B18: Phonak JP Contents Update_discontinuedProductList | C18: =SUMIFS(Data!$H:$H,Data!$A:$A,DATE(2026,8,11),Data!$B:$B,"CWL-2922") -> 2 | D18: =ROUND(SUMIFS(Data!$D:$D,Data!$A:$A,DATE(2026,8,11),Data!$B:$B,"CWL-2922"),2) -> 0.83 | E18: Medium | F18: DONE
A19: CWL-2869 | B19: HT_Website_PhaseoutUpdate-June26 | C19: =SUMIFS(Data!$H:$H,Data!$A:$A,DATE(2026,8,11),Data!$B:$B,"CWL-2869") -> 3 | D19: =ROUND(SUMIFS(Data!$D:$D,Data!$A:$A,DATE(2026,8,11),Data!$B:$B,"CWL-2869"),2) -> 6 | E19: Medium | F19: DONE
A20: CWL-2920 | B20: HT_Website_France-S3-2026 Update | C20: =SUMIFS(Data!$H:$H,Data!$A:$A,DATE(2026,8,11),Data!$B:$B,"CWL-2920") -> 2 | D20: =ROUND(SUMIFS(Data!$D:$D,Data!$A:$A,DATE(2026,8,11),Data!$B:$B,"CWL-2920"),2) -> 6 | E20: Medium | F20: WAITING FOR APPROVAL (MIGRATED)
A21: CWL-2910 | B21: Updating customer information on the Unitron website | C21: =SUMIFS(Data!$H:$H,Data!$A:$A,DATE(2026,8,11),Data!$B:$B,"CWL-2910") -> 1 | D21: =ROUND(SUMIFS(Data!$D:$D,Data!$A:$A,DATE(2026,8,11),Data!$B:$B,"CWL-2910"),2) -> 1 | E21: Medium | F21: WAITING FOR APPROVAL (MIGRATED)
A22: CWL-2889 | B22: New Roger On page for the launch S3-26 | C22: =SUMIFS(Data!$H:$H,Data!$A:$A,DATE(2026,8,11),Data!$B:$B,"CWL-2889") -> 1 | D22: =ROUND(SUMIFS(Data!$D:$D,Data!$A:$A,DATE(2026,8,11),Data!$B:$B,"CWL-2889"),2) -> 5.5 | E22: Medium | F22: WAITING FOR APPROVAL (MIGRATED)
A23: CWL-2923 | B23: Request form update | C23: =SUMIFS(Data!$H:$H,Data!$A:$A,DATE(2026,8,11),Data!$B:$B,"CWL-2923") -> 2 | D23: =ROUND(SUMIFS(Data!$D:$D,Data!$A:$A,DATE(2026,8,11),Data!$B:$B,"CWL-2923"),2) -> 1.17 | E23: Medium | F23: WAITING FOR APPROVAL (MIGRATED)
A24: CWL-2464 | B24: Move Phonak Hearing Stories to new Blog Component | C24: =SUMIFS(Data!$H:$H,Data!$A:$A,DATE(2026,8,11),Data!$B:$B,"CWL-2464") -> 4 | D24: =ROUND(SUMIFS(Data!$D:$D,Data!$A:$A,DATE(2026,8,11),Data!$B:$B,"CWL-2464"),2) -> 15.25 | E24: Low | F24: IN PROGRESS
A25: CWL-2918 | B25: (cwl)Need to add a new Roger evidence | C25: =SUMIFS(Data!$H:$H,Data!$A:$A,DATE(2026,8,11),Data!$B:$B,"CWL-2918") -> 1 | D25: =ROUND(SUMIFS(Data!$D:$D,Data!$A:$A,DATE(2026,8,11),Data!$B:$B,"CWL-2918"),2) -> 0.17 | E25: Medium | F25: DONE
A26: CWL-2919 | B26: HT_Website_International_PL-Userguide-Upload | C26: =SUMIFS(Data!$H:$H,Data!$A:$A,DATE(2026,8,11),Data!$B:$B,"CWL-2919") -> 1 | D26: =ROUND(SUMIFS(Data!$D:$D,Data!$A:$A,DATE(2026,8,11),Data!$B:$B,"CWL-2919"),2) -> 0.25 | E26: Medium | F26: DONE
A27: ="Day Total ("&COUNTA(A16:A26)&" tickets)" -> Day Total (11 tickets) | D27: =ROUND(SUM(D16:D26),2) -> 49.67
A29: Wednesday, 2026-08-12 | Team Availability: 7/7 | New Tickets Created: 1
A30: Ticket Key | B30: Summary | C30: Authors on Ticket | D30: Hours Logged | E30: Priority | F30: Status
A31: CWL-2916 | B31: Ad hoc: August | C31: =SUMIFS(Data!$H:$H,Data!$A:$A,DATE(2026,8,12),Data!$B:$B,"CWL-2916") -> 7 | D31: =ROUND(SUMIFS(Data!$D:$D,Data!$A:$A,DATE(2026,8,12),Data!$B:$B,"CWL-2916"),2) -> 7.5 | E31: Low | F31: TICKET ACKNOWLEDGEMENT
A32: CWL-2889 | B32: New Roger On page for the launch S3-26 | C32: =SUMIFS(Data!$H:$H,Data!$A:$A,DATE(2026,8,12),Data!$B:$B,"CWL-2889") -> 1 | D32: =ROUND(SUMIFS(Data!$D:$D,Data!$A:$A,DATE(2026,8,12),Data!$B:$B,"CWL-2889"),2) -> 2 | E32: Medium | F32: WAITING FOR APPROVAL (MIGRATED)
A33: CWL-2869 | B33: HT_Website_PhaseoutUpdate-June26 | C33: =SUMIFS(Data!$H:$H,Data!$A:$A,DATE(2026,8,12),Data!$B:$B,"CWL-2869") -> 1 | D33: =ROUND(SUMIFS(Data!$D:$D,Data!$A:$A,DATE(2026,8,12),Data!$B:$B,"CWL-2869"),2) -> 0.5 | E33: Medium | F33: DONE
A34: CWL-2464 | B34: Move Phonak Hearing Stories to new Blog Component | C34: =SUMIFS(Data!$H:$H,Data!$A:$A,DATE(2026,8,12),Data!$B:$B,"CWL-2464") -> 7 | D34: =ROUND(SUMIFS(Data!$D:$D,Data!$A:$A,DATE(2026,8,12),Data!$B:$B,"CWL-2464"),2) -> 33.67 | E34: Low | F34: IN PROGRESS
A35: CWL-2918 | B35: (cwl)Need to add a new Roger evidence | C35: =SUMIFS(Data!$H:$H,Data!$A:$A,DATE(2026,8,12),Data!$B:$B,"CWL-2918") -> 1 | D35: =ROUND(SUMIFS(Data!$D:$D,Data!$A:$A,DATE(2026,8,12),Data!$B:$B,"CWL-2918"),2) -> 0.42 | E35: Medium | F35: DONE
A36: CWL-2921 | B36: Create a new "Conditions Générales de Vente" page for each webiste brand and add a footer link on the French Phonak, Unitron and Hansaton websites | C36: =SUMIFS(Data!$H:$H,Data!$A:$A,DATE(2026,8,12),Data!$B:$B,"CWL-2921") -> 1 | D36: =ROUND(SUMIFS(Data!$D:$D,Data!$A:$A,DATE(2026,8,12),Data!$B:$B,"CWL-2921"),2) -> 3.75 | E36: Medium | F36: APPROVED FOR ACTIVATION
A37: CWL-2920 | B37: HT_Website_France-S3-2026 Update | C37: =SUMIFS(Data!$H:$H,Data!$A:$A,DATE(2026,8,12),Data!$B:$B,"CWL-2920") -> 1 | D37: =ROUND(SUMIFS(Data!$D:$D,Data!$A:$A,DATE(2026,8,12),Data!$B:$B,"CWL-2920"),2) -> 0.5 | E37: Medium | F37: WAITING FOR APPROVAL (MIGRATED)
A38: ="Day Total ("&COUNTA(A31:A37)&" tickets)" -> Day Total (7 tickets) | D38: =ROUND(SUM(D31:D37),2) -> 48.34
A40: Thursday, 2026-08-13 | Team Availability: 7/7 | New Tickets Created: 3
A41: Ticket Key | B41: Summary | C41: Authors on Ticket | D41: Hours Logged | E41: Priority | F41: Status
A42: CWL-2912 | B42: New WCB Manitoba grid version | C42: =SUMIFS(Data!$H:$H,Data!$A:$A,DATE(2026,8,13),Data!$B:$B,"CWL-2912") -> 1 | D42: =ROUND(SUMIFS(Data!$D:$D,Data!$A:$A,DATE(2026,8,13),Data!$B:$B,"CWL-2912"),2) -> 0.25 | E42: Medium | F42: DONE
A43: CWL-2916 | B43: Ad hoc: August | C43: =SUMIFS(Data!$H:$H,Data!$A:$A,DATE(2026,8,13),Data!$B:$B,"CWL-2916") -> 7 | D43: =ROUND(SUMIFS(Data!$D:$D,Data!$A:$A,DATE(2026,8,13),Data!$B:$B,"CWL-2916"),2) -> 7.5 | E43: Low | F43: TICKET ACKNOWLEDGEMENT
A44: CWL-2924 | B44: Roger VIP Launch Event - Landing Page | C44: =SUMIFS(Data!$H:$H,Data!$A:$A,DATE(2026,8,13),Data!$B:$B,"CWL-2924") -> 2 | D44: =ROUND(SUMIFS(Data!$D:$D,Data!$A:$A,DATE(2026,8,13),Data!$B:$B,"CWL-2924"),2) -> 1.08 | E44: Medium | F44: DONE
...

Sheet Dashboard
A1: Weekly Report - Visual Summary
A3: Hours Logged Per Day | D3: Hours Logged Per Author | G3: Tickets By Priority
A4: Date | B4: Hours | D4: Author | E4: Hours | G4: Priority | H4: Count
A5: 2026-08-10 | B5: 41.02 | D5: User 1 | E5: 33.75 | G5: Low | H5: 2
A6: 2026-08-11 | B6: 49.67 | D6: User 2 | E6: 27.6 | G6: Medium | H6: 15
A7: 2026-08-12 | B7: 48.33 | D7: User 3 | E7: 36.83
A8: 2026-08-13 | B8: 48.5 | D8: User 4 | E8: 33.5
A9: 2026-08-14 | B9: 36.25 | D9: User 5 | E9: 30.42
D10: User 6 | E10: 26.25
D11: User 7 | E11: 35.42

Sheet Tickets Created This Week
A1: New Tickets Created This Week
A3: Ticket Key | B3: Summary | C3: Status | D3: Priority | E3: Date Created
A4: CWL-2921 | B4: Create a new "Conditions Générales de Vente" page for each webiste brand and add a footer link on the French Phonak, Unitron and Hansaton websites | C4: Approved for Activation | D4: Medium | E4: 46244
A5: CWL-2922 | B5: Phonak JP Contents Update_discontinuedProductList | C5: Done | D5: Medium | E5: 46244
A6: CWL-2923 | B6: Request form update | C6: Waiting for Approval (migrated) | D6: Medium | E6: 46244
A7: CWL-2924 | B7: Roger VIP Launch Event - Landing Page | C7: Done | D7: Medium | E7: 46246
A8: CWL-2925 | B8: Removal of components Moxi V-RS | C8: Done | D8: Medium | E8: 46247
A9: CWL-2926 | B9: Brazil Hansaton Website Update - User Guides | C9: Waiting for Approval (migrated) | D9: Medium | E9: 46247
A10: CWL-2927 | B10: Add Wang journal to evidence library webpage | C10: Done | D10: Medium | E10: 46247
A12: Total Tickets Created | E12: =COUNTA(A4:A10) -> 7

Sheet Author Summary (Anonymized)
A1: Author Summary (Anonymized)
A2: Names withheld; each team member is identified only by an anonymized ID
A4: Author ID | B4: 2026-08-09 | C4: 2026-08-10 | D4: 2026-08-11 | E4: 2026-08-12 | F4: 2026-08-13 | G4: 2026-08-14 | H4: 2026-08-15 | I4: Total Hours Logged
A5: User 1 | B5: 0 | C5: 6.5 | D5: 7 | E5: 6.5 | F5: 6.75 | G5: 7 | H5: 0 | I5: =ROUND(SUM(B5:H5),2) -> 33.75
A6: User 2 | B6: 0 | C6: 7.1 | D6: 6.5 | E6: 6.42 | F6: 6.58 | G6: 1 | H6: 0 | I6: =ROUND(SUM(B6:H6),2) -> 27.6
A7: User 3 | B7: 0 | C7: 7.17 | D7: 7.17 | E7: 7.75 | F7: 7.17 | G7: 7.58 | H7: 0 | I7: =ROUND(SUM(B7:H7),2) -> 36.84
A8: User 4 | B8: 0 | C8: 6.5 | D8: 7 | E8: 7 | F8: 6.25 | G8: 6.75 | H8: 0 | I8: =ROUND(SUM(B8:H8),2) -> 33.5
A9: User 5 | B9: 0 | C9: 1 | D9: 7.5 | E9: 7.17 | F9: 7.5 | G9: 7.25 | H9: 0 | I9: =ROUND(SUM(B9:H9),2) -> 30.42
A10: User 6 | B10: 0 | C10: 6 | D10: 7.25 | E10: 6.5 | F10: 6.5 | G10: 0 | H10: 0 | I10: =ROUND(SUM(B10:H10),2) -> 26.25
A11: User 7 | B11: 0 | C11: 6.75 | D11: 7.25 | E11: 7 | F11: 7.75 | G11: 6.67 | H11: 0 | I11: =ROUND(SUM(B11:H11),2) -> 35.42
A12: Team Total | B12: =ROUND(SUM(B5:B11),2) -> 0 | C12: =ROUND(SUM(C5:C11),2) -> 41.02 | D12: =ROUND(SUM(D5:D11),2) -> 49.67 | E12: =ROUND(SUM(E5:E11),2) -> 48.34 | F12: =ROUND(SUM(F5:F11),2) -> 48.5 | G12: =ROUND(SUM(G5:G11),2) -> 36.25 | H12: =ROUND(SUM(H5:H11),2) -> 0 | I12: =ROUND(SUM(I5:I11),2) -> 223.78

Sheet Data
A1: Date | B1: Ticket Key | C1: Summary | D1: Hours | E1: AuthorID | F1: Status | G1: Priority | H1: FirstAuthorTicketDay | I1: FirstAuthorDay | J1: FirstTicketWeek
A2: 46244 | B2: CWL-2916 | C2: Ad hoc: August | D2: 1 | E2: User 1 | F2: TICKET ACKNOWLEDGEMENT | G2: Low | H2: =IF(COUNTIFS($A$2:A2,A2,$B$2:B2,B2,$E$2:E2,E2)=1,1,0) -> 1 | I2: =IF(COUNTIFS($A$2:A2,A2,$E$2:E2,E2)=1,1,0) -> 1 | J2: =IF(COUNTIFS($B$2:B2,B2)=1,1,0) -> 1
A3: 46244 | B3: CWL-2916 | C3: Ad hoc: August | D3: 1 | E3: User 5 | F3: TICKET ACKNOWLEDGEMENT | G3: Low | H3: =IF(COUNTIFS($A$2:A3,A3,$B$2:B3,B3,$E$2:E3,E3)=1,1,0) -> 1 | I3: =IF(COUNTIFS($A$2:A3,A3,$E$2:E3,E3)=1,1,0) -> 1 | J3: =IF(COUNTIFS($B$2:B3,B3)=1,1,0) -> 0
A4: 46244 | B4: CWL-2916 | C4: Ad hoc: August | D4: 1 | E4: User 2 | F4: TICKET ACKNOWLEDGEMENT | G4: Low | H4: =IF(COUNTIFS($A$2:A4,A4,$B$2:B4,B4,$E$2:E4,E4)=1,1,0) -> 1 | I4: =IF(COUNTIFS($A$2:A4,A4,$E$2:E4,E4)=1,1,0) -> 1 | J4: =IF(COUNTIFS($B$2:B4,B4)=1,1,0) -> 0
A5: 46244 | B5: CWL-2890 | C5: 2026_S3_LC Virto Charger Go - Web page updates | D5: 0.25 | E5: User 7 | F5: DONE | G5: Medium | H5: =IF(COUNTIFS($A$2:A5,A5,$B$2:B5,B5,$E$2:E5,E5)=1,1,0) -> 1 | I5: =IF(COUNTIFS($A$2:A5,A5,$E$2:E5,E5)=1,1,0) -> 1 | J5: =IF(COUNTIFS($B$2:B5,B5)=1,1,0) -> 1
A6: 46244 | B6: CWL-2916 | C6: Ad hoc: August | D6: 1 | E6: User 3 | F6: TICKET ACKNOWLEDGEMENT | G6: Low | H6: =IF(COUNTIFS($A$2:A6,A6,$B$2:B6,B6,$E$2:E6,E6)=1,1,0) -> 1 | I6: =IF(COUNTIFS($A$2:A6,A6,$E$2:E6,E6)=1,1,0) -> 1 | J6: =IF(COUNTIFS($B$2:B6,B6)=1,1,0) -> 0
A7: 46244 | B7: CWL-2916 | C7: Ad hoc: August | D7: 1 | E7: User 6 | F7: TICKET ACKNOWLEDGEMENT | G7: Low | H7: =IF(COUNTIFS($A$2:A7,A7,$B$2:B7,B7,$E$2:E7,E7)=1,1,0) -> 1 | I7: =IF(COUNTIFS($A$2:A7,A7,$E$2:E7,E7)=1,1,0) -> 1 | J7: =IF(COUNTIFS($B$2:B7,B7)=1,1,0) -> 0
A8: 46244 | B8: CWL-2869 | C8: HT_Website_PhaseoutUpdate-June26 | D8: 1.5 | E8: User 4 | F8: DONE | G8: Medium | H8: =IF(COUNTIFS($A$2:A8,A8,$B$2:B8,B8,$E$2:E8,E8)=1,1,0) -> 1 | I8: =IF(COUNTIFS($A$2:A8,A8,$E$2:E8,E8)=1,1,0) -> 1 | J8: =IF(COUNTIFS($B$2:B8,B8)=1,1,0) -> 1
A9: 46244 | B9: CWL-2916 | C9: Ad hoc: August | D9: 1 | E9: User 7 | F9: TICKET ACKNOWLEDGEMENT | G9: Low | H9: =IF(COUNTIFS($A$2:A9,A9,$B$2:B9,B9,$E$2:E9,E9)=1,1,0) -> 1 | I9: =IF(COUNTIFS($A$2:A9,A9,$E$2:E9,E9)=1,1,0) -> 0 | J9: =IF(COUNTIFS($B$2:B9,B9)=1,1,0) -> 0
A10: 46244 | B10: CWL-2464 | C10: Move Phonak Hearing Stories to new Blog Component | D10: 1 | E10: User 1 | F10: IN PROGRESS | G10: Low | H10: =IF(COUNTIFS($A$2:A10,A10,$B$2:B10,B10,$E$2:E10,E10)=1,1,0) -> 1 | I10: =IF(COUNTIFS($A$2:A10,A10,$E$2:E10,E10)=1,1,0) -> 0 | J10: =IF(COUNTIFS($B$2:B10,B10)=1,1,0) -> 1
A11: 46244 | B11: CWL-2464 | C11: Move Phonak Hearing Stories to new Blog Component | D11: 6.1 | E11: User 2 | F11: IN PROGRESS | G11: Low | H11: =IF(COUNTIFS($A$2:A11,A11,$B$2:B11,B11,$E$2:E11,E11)=1,1,0) -> 1 | I11: =IF(COUNTIFS($A$2:A11,A11,$E$2:E11,E11)=1,1,0) -> 0 | J11: =IF(COUNTIFS($B$2:B11,B11)=1,1,0) -> 0
A12: 46244 | B12: CWL-2916 | C12: Ad hoc: August | D12: 0.5 | E12: User 3 | F12: TICKET ACKNOWLEDGEMENT | G12: Low | H12: =IF(COUNTIFS($A$2:A12,A12,$B$2:B12,B12,$E$2:E12,E12)=1,1,0) -> 0 | I12: =IF(COUNTIFS($A$2:A12,A12,$E$2:E12,E12)=1,1,0) -> 0 | J12: =IF(COUNTIFS($B$2:B12,B12)=1,1,0) -> 0
A13: 46244 | B13: CWL-2890 | C13: 2026_S3_LC Virto Charger Go - Web page updates | D13: 0.5 | E13: User 6 | F13: DONE | G13: Medium | H13: =IF(COUNTIFS($A$2:A13,A13,$B$2:B13,B13,$E$2:E13,E13)=1,1,0) -> 1 | I13: =IF(COUNTIFS($A$2:A13,A13,$E$2:E13,E13)=1,1,0) -> 0 | J13: =IF(COUNTIFS($B$2:B13,B13)=1,1,0) -> 0
... A121: 46248 | B121: CWL-2464 | C121: Move Phonak Hearing Stories to new Blog Component | D121: 3.5 | E121: User 1 | F121: IN PROGRESS | G121: Low | H121: =IF(COUNTIFS($A$2:A121,A121,$B$2:B121,B121,$E$2:E121,E121)=1,1,0) -> 1 | I121: =IF(COUNTIFS($A$2:A121,A121,$E$2:E121,E121)=1,1,0) -> 0 | J121: =IF(COUNTIFS($B$2:B121,B121)=1,1,0) -> 0

Sheet Internal Ref - DO NOT SHARE
A1: INTERNAL USE ONLY - remove this sheet before presenting to the team
A2: Author ID | B2: Real Name
A3: User 1 | B3: Daundkar, Mukul External
A4: User 2 | B4: Joshi, Chaitanya External
A5: User 3 | B5: Kale, Sonali External
A6: User 4 | B6: Shinde, Dakshata External
A7: User 5 | B7: Shinde, Sayali External
A8: User 6 | B8: Shirvatkar, Yadnesh External
A9: User 7 | B9: Yamanollu, Anjaneyulu External
