Workbook

Sheet Worklogs
A1: Work Item Key | B1: Work Item summary | C1: Logged Hours | D1: Logged Seconds | E1: Work date | F1: User Account ID | G1: Full name | H1: Tempo Team | I1: Team Lead ID | J1: Program | K1: Program Manager ID | L1: Period | M1: Account Key | N1: Account Name | O1: Account Status | P1: Account Lead ID | Q1: Account Category | R1: Account Category Type | S1: Account Customer | T1: Account Contact ID | U1: Account Contact External | V1: Activity Name | W1: Component | X1: All Components | Y1: Version Name | Z1: Work Item Type | AA1: Work Item Status | AB1: Priority | AC1: Space Key | AD1: Space Name | AE1: Epic | AF1: Epic Link | AG1: Work Description | AH1: Parent Key | AI1: Reporter ID | AJ1: Assignee ID | AK1: External Hours | AL1: Billable Hours | AM1: Billable Seconds | AN1: Work Item Original Estimate Hours | AO1: Work Item Original Estimate Seconds | AP1: Work Item Remaining Estimate Hours | AQ1: Work Item Remaining Estimate Seconds | AR1: Approval status | AS1: Date created | AT1: Date updated | AU1: Tempo Worklog ID
A2: CWL-2938 | B2: Please upload updated MDR DoC documents to the Phonak Certificates page and removed the older documents | C2: 5.333 | D2: 19200 | E2: 2026-09-01 08:00 | F2: 712020:bff05832-15dc-4ee5-a497-e1c8f7ccef4b | G2: Shinde, Dakshata External | H2: Capgemini | I2: 63f8addd8ab3d6a635ee03fe | L2: 0926 | V2: Capgemini Web Localization | Z2: Task | AA2: DONE | AB2: Medium | AC2: CWL | AD2: Capgemini Web Localization | AG2: 24 documents uploaded in DAM, Added Title in each document properties. Adding document on masters 8/18 Updated Download component labels | AI2: 6150d70078e5e40070f10fcf | AJ2: 6150d70078e5e40070f10fcf | AL2: 5.333 | AM2: 19200 | AR2: Open | AS2: 2026-09-02 11:31 | AT2: 2026-09-02 11:31 | AU2: 87912
A3: CWL-2956 | B3: Ad hoc: September | C3: 1 | D3: 3600 | E3: 2026-09-01 13:20 | F3: 712020:bff05832-15dc-4ee5-a497-e1c8f7ccef4b | G3: Shinde, Dakshata External | H3: Capgemini | I3: 63f8addd8ab3d6a635ee03fe | L3: 0926 | V3: Capgemini Web Localization | Z3: Epic | AA3: RESOLVED | AB3: Medium | AC3: CWL | AD3: Capgemini Web Localization | AE3: Ad hoc: September | AG3: Daily calls | AI3: 712020:43d154d7-2f24-4544-aee8-18a7991cad72 | AJ3: 712020:43d154d7-2f24-4544-aee8-18a7991cad72 | AL3: 1 | AM3: 3600 | AN3: 240 | AO3: 864000 | AP3: 104.5 | AQ3: 376200 | AR3: Open | AS3: 2026-09-02 11:33 | AT3: 2026-09-02 11:33 | AU3: 87915
A4: CWL-2938 | B4: Please upload updated MDR DoC documents to the Phonak Certificates page and removed the older documents | C4: 6.5 | D4: 23400 | E4: 2026-09-02 08:00 | F4: 712020:bff05832-15dc-4ee5-a497-e1c8f7ccef4b | G4: Shinde, Dakshata External | H4: Capgemini | I4: 63f8addd8ab3d6a635ee03fe | L4: 0926 | V4: Capgemini Web Localization | Z4: Task | AA4: DONE | AB4: Medium | AC4: CWL | AD4: Capgemini Web Localization | AG4: 24 documents uploaded in DAM, Added Title in each document properties. Adding document on masters 18 pages done Updated Download component labels | AI4: 6150d70078e5e40070f10fcf | AJ4: 6150d70078e5e40070f10fcf | AL4: 6.5 | AM4: 23400 | AR4: Open | AS4: 2026-09-02 11:33 | AT4: 2026-09-02 11:33 | AU4: 87913
A5: CWL-2956 | B5: Ad hoc: September | C5: 1 | D5: 3600 | E5: 2026-09-02 14:30 | F5: 712020:bff05832-15dc-4ee5-a497-e1c8f7ccef4b | G5: Shinde, Dakshata External | H5: Capgemini | I5: 63f8addd8ab3d6a635ee03fe | L5: 0926 | V5: Capgemini Web Localization | Z5: Epic | AA5: RESOLVED | AB5: Medium | AC5: CWL | AD5: Capgemini Web Localization | AE5: Ad hoc: September | AG5: Daily calls | AI5: 712020:43d154d7-2f24-4544-aee8-18a7991cad72 | AJ5: 712020:43d154d7-2f24-4544-aee8-18a7991cad72 | AL5: 1 | AM5: 3600 | AN5: 240 | AO5: 864000 | AP5: 104.5 | AQ5: 376200 | AR5: Open | AS5: 2026-09-02 11:33 | AT5: 2026-09-02 11:33 | AU5: 87914
A6: CWL-2926 | B6: Brazil Hansaton Website Update - User Guides | C6: 0.167 | D6: 600 | E6: 2026-09-03 08:00 | F6: 712020:bff05832-15dc-4ee5-a497-e1c8f7ccef4b | G6: Shinde, Dakshata External | H6: Capgemini | I6: 63f8addd8ab3d6a635ee03fe | L6: 0926 | V6: Capgemini Web Localization | Z6: Task | AA6: DONE | AB6: Medium | AC6: CWL | AD6: Capgemini Web Localization | AG6: Activation, live review, comment | AI6: 712020:0bb4520e-88ad-4944-b05c-757ccdced91f | AJ6: 712020:0bb4520e-88ad-4944-b05c-757ccdced91f | AL6: 0.167 | AM6: 600 | AR6: Open | AS6: 2026-09-03 07:27 | AT6: 2026-09-03 07:27 | AU6: 87953
A7: CWL-2943 | B7: HT_Website_Software Update Download Center 5.10.1 | C7: 0.333 | D7: 1200 | E7: 2026-09-03 08:10 | F7: 712020:bff05832-15dc-4ee5-a497-e1c8f7ccef4b | G7: Shinde, Dakshata External | H7: Capgemini | I7: 63f8addd8ab3d6a635ee03fe | L7: 0926 | V7: Capgemini Web Localization | Z7: Task | AA7: DONE | AB7: Medium | AC7: CWL | AD7: Capgemini Web Localization | AG7: Activation, live review, comments | AI7: 6052fd65695c39007071a1b5 | AJ7: 6052fd65695c39007071a1b5 | AL7: 0.333 | AM7: 1200 | AR7: Open | AS7: 2026-09-03 13:51 | AT7: 2026-09-03 13:51 | AU7: 87983
A8: CWL-2942 | B8: HT_Website_Download Center Spain | C8: 0.167 | D8: 600 | E8: 2026-09-03 08:30 | F8: 712020:bff05832-15dc-4ee5-a497-e1c8f7ccef4b | G8: Shinde, Dakshata External | H8: Capgemini | I8: 63f8addd8ab3d6a635ee03fe | L8: 0926 | V8: Capgemini Web Localization | Z8: Task | AA8: DONE | AB8: Medium | AC8: CWL | AD8: Capgemini Web Localization | AG8: Activation, live review, comment | AI8: 6052fd65695c39007071a1b5 | AJ8: 6052fd65695c39007071a1b5 | AL8: 0.167 | AM8: 600 | AR8: Open | AS8: 2026-09-03 13:51 | AT8: 2026-09-03 13:51 | AU8: 87984
A9: CWL-2956 | B9: Ad hoc: September | C9: 1 | D9: 3600 | E9: 2026-09-03 08:40 | F9: 712020:bff05832-15dc-4ee5-a497-e1c8f7ccef4b | G9: Shinde, Dakshata External | H9: Capgemini | I9: 63f8addd8ab3d6a635ee03fe | L9: 0926 | V9: Capgemini Web Localization | Z9: Epic | AA9: RESOLVED | AB9: Medium | AC9: CWL | AD9: Capgemini Web Localization | AE9: Ad hoc: September | AG9: Daily calls | AI9: 712020:43d154d7-2f24-4544-aee8-18a7991cad72 | AJ9: 712020:43d154d7-2f24-4544-aee8-18a7991cad72 | AL9: 1 | AM9: 3600 | AN9: 240 | AO9: 864000 | AP9: 104.5 | AQ9: 376200 | AR9: Open | AS9: 2026-09-03 13:52 | AT9: 2026-09-03 13:52 | AU9: 87985
A10: CWL-2938 | B10: Please upload updated MDR DoC documents to the Phonak Certificates page and removed the older documents | C10: 0.333 | D10: 1200 | E10: 2026-09-03 09:40 | F10: 712020:bff05832-15dc-4ee5-a497-e1c8f7ccef4b | G10: Shinde, Dakshata External | H10: Capgemini | I10: 63f8addd8ab3d6a635ee03fe | L10: 0926 | V10: Capgemini Web Localization | Z10: Task | AA10: DONE | AB10: Medium | AC10: CWL | AD10: Capgemini Web Localization | AG10: Country pages done | AI10: 6150d70078e5e40070f10fcf | AJ10: 6150d70078e5e40070f10fcf | AL10: 0.333 | AM10: 1200 | AR10: Open | AS10: 2026-09-04 13:23 | AT10: 2026-09-04 13:23 | AU10: 88025
A11: CWL-2958 | B11: Localization PH s3 - DE | C11: 6 | D11: 21600 | E11: 2026-09-03 10:00 | F11: 712020:bff05832-15dc-4ee5-a497-e1c8f7ccef4b | G11: Shinde, Dakshata External | H11: Capgemini | I11: 63f8addd8ab3d6a635ee03fe | L11: 0926 | V11: Capgemini Web Localization | Z11: Task | AA11: DONE | AB11: Medium | AC11: CWL | AD11: Capgemini Web Localization | AF11: PH_S3_26 | AG11: Master pages : 16 pages Audeo EON - Overview,Features,For professionals - 1h 15m Audeo EON Sphere - Overview,Features,For professionals- 1h 15m CROS EON - Overview,Features,For professionals- 1h 15m Hearing aids page -10 m New at Phonak -45 m Target user guides - 1h / 42documents, label translation User guides EON -10 m User guides Charger - 10m User guides- 5m | AH11: MOR-17113 | AI11: 613a1c0e24ba8b00701d6a93 | AJ11: 613a1c0e24ba8b00701d6a93 | AL11: 6 | AM11: 21600 | AN11: 8 | AO11: 28800 | AP11: 0 | AQ11: 0 | AR11: Open | AS11: 2026-09-07 05:59 | AT11: 2026-09-07 05:59 | AU11: 88084
A12: CWL-2956 | B12: Ad hoc: September | C12: 1 | D12: 3600 | E12: 2026-09-04 08:00 | F12: 712020:bff05832-15dc-4ee5-a497-e1c8f7ccef4b | G12: Shinde, Dakshata External | H12: Capgemini | I12: 63f8addd8ab3d6a635ee03fe | L12: 0926 | V12: Capgemini Web Localization | Z12: Epic | AA12: RESOLVED | AB12: Medium | AC12: CWL | AD12: Capgemini Web Localization | AE12: Ad hoc: September | AG12: Daily calls | AI12: 712020:43d154d7-2f24-4544-aee8-18a7991cad72 | AJ12: 712020:43d154d7-2f24-4544-aee8-18a7991cad72 | AL12: 1 | AM12: 3600 | AN12: 240 | AO12: 864000 | AP12: 104.5 | AQ12: 376200 | AR12: Open | AS12: 2026-09-04 13:20 | AT12: 2026-09-04 13:20 | AU12: 88024
A13: CWL-2958 | B13: Localization PH s3 - DE | C13: 6.8 | D13: 24480 | E13: 2026-09-04 09:00 | F13: 712020:bff05832-15dc-4ee5-a497-e1c8f7ccef4b | G13: Shinde, Dakshata External | H13: Capgemini | I13: 63f8addd8ab3d6a635ee03fe | L13: 0926 | V13: Capgemini Web Localization | Z13: Task | AA13: DONE | AB13: Medium | AC13: CWL | AD13: Capgemini Web Localization | AF13: PH_S3_26 | AG13: 3 Country updates Audeo EON - Cf,Footnotes, links, Overview,Features,For professionals - 1h 21m Audeo EON Sphere - Cf,Footnotes, links, Overview,Features,For professionals- 1h 21m CROS EON - Cf,Footnotes, links,Overview,Features,For professionals- 1h 21m Hearing aids page -15m New at Phonak -30 m Target user guides - 30m / 42documents, label translation User guides EON -15 m User guides Charger - 15m User guides- 15m Navigation Manually for 3 countries - 45m | AH13: MOR-17113 | AI13: 613a1c0e24ba8b00701d6a93 | AJ13: 613a1c0e24ba8b00701d6a93 | AL13: 6.8 | AM13: 24480 | AN13: 8 | AO13: 28800 | AP13: 0 | AQ13: 0 | AR13: Open | AS13: 2026-09-07 06:05 | AT13: 2026-09-07 06:05 | AU13: 88088
A14: CWL-2956 | B14: Ad hoc: September | C14: 1 | D14: 3600 | E14: 2026-09-07 08:00 | F14: 712020:bff05832-15dc-4ee5-a497-e1c8f7ccef4b | G14: Shinde, Dakshata External | H14: Capgemini | I14: 63f8addd8ab3d6a635ee03fe | L14: 0926 | V14: Capgemini Web Localization | Z14: Epic | AA14: RESOLVED | AB14: Medium | AC14: CWL | AD14: Capgemini Web Localization | AE14: Ad hoc: September | AG14: Daily calls | AI14: 712020:43d154d7-2f24-4544-aee8-18a7991cad72 | AJ14: 712020:43d154d7-2f24-4544-aee8-18a7991cad72 | AL14: 1 | AM14: 3600 | AN14: 240 | AO14: 864000 | AP14: 104.5 | AQ14: 376200 | AR14: Open | AS14: 2026-09-10 10:22 | AT14: 2026-09-10 10:22 | AU14: 88247
A15: CWL-2955 | B15: Update of Support Banner Into Content Fragment | C15: 5 | D15: 18000 | E15: 2026-09-07 09:00 | F15: 712020:bff05832-15dc-4ee5-a497-e1c8f7ccef4b | G15: Shinde, Dakshata External | H15: Capgemini | I15: 63f8addd8ab3d6a635ee03fe | L15: 0926 | V15: Capgemini Web Localization | Z15: Task | AA15: IN PROGRESS | AB15: Medium | AC15: CWL | AD15: Capgemini Web Localization | AG15: DK Master 109 Country 50 pages done | AI15: 613a1c0e24ba8b00701d6a93 | AJ15: 712020:3c2be4d6-9205-4a56-b7d8-1f2bb88ce234 | AL15: 5 | AM15: 18000 | AN15: 24 | AO15: 86400 | AP15: 0 | AQ15: 0 | AR15: Open | AS15: 2026-09-10 11:39 | AT15: 2026-09-10 11:39 | AU15: 88258
A16: CWL-2956 | B16: Ad hoc: September | C16: 1 | D16: 3600 | E16: 2026-09-08 08:00 | F16: 712020:bff05832-15dc-4ee5-a497-e1c8f7ccef4b | G16: Shinde, Dakshata External | H16: Capgemini | I16: 63f8addd8ab3d6a635ee03fe | L16: 0926 | V16: Capgemini Web Localization | Z16: Epic | AA16: RESOLVED | AB16: Medium | AC16: CWL | AD16: Capgemini Web Localization | AE16: Ad hoc: September | AG16: Daily calls | AI16: 712020:43d154d7-2f24-4544-aee8-18a7991cad72 | AJ16: 712020:43d154d7-2f24-4544-aee8-18a7991cad72 | AL16: 1 | AM16: 3600 | AN16: 240 | AO16: 864000 | AP16: 104.5 | AQ16: 376200 | AR16: Open | AS16: 2026-09-10 10:21 | AT16: 2026-09-10 10:21 | AU16: 88246
A17: CWL-2955 | B17: Update of Support Banner Into Content Fragment | C17: 5.167 | D17: 18600 | E17: 2026-09-08 09:00 | F17: 712020:bff05832-15dc-4ee5-a497-e1c8f7ccef4b | G17: Shinde, Dakshata External | H17: Capgemini | I17: 63f8addd8ab3d6a635ee03fe | L17: 0926 | V17: Capgemini Web Localization | Z17: Task | AA17: IN PROGRESS | AB17: Medium | AC17: CWL | AD17: Capgemini Web Localization | AG17: 52 pages done DK country BE NL 113 links done | AI17: 613a1c0e24ba8b00701d6a93 | AJ17: 712020:3c2be4d6-9205-4a56-b7d8-1f2bb88ce234 | AL17: 5.167 | AM17: 18600 | AN17: 24 | AO17: 86400 | AP17: 0 | AQ17: 0 | AR17: Open | AS17: 2026-09-10 11:41 | AT17: 2026-09-10 11:41 | AU17: 88259
A18: CWL-2956 | B18: Ad hoc: September | C18: 1 | D18: 3600 | E18: 2026-09-09 08:00 | F18: 712020:bff05832-15dc-4ee5-a497-e1c8f7ccef4b | G18: Shinde, Dakshata External | H18: Capgemini | I18: 63f8addd8ab3d6a635ee03fe | L18: 0926 | V18: Capgemini Web Localization | Z18: Epic | AA18: RESOLVED | AB18: Medium | AC18: CWL | AD18: Capgemini Web Localization | AE18: Ad hoc: September | AG18: Daily calls | AI18: 712020:43d154d7-2f24-4544-aee8-18a7991cad72 | AJ18: 712020:43d154d7-2f24-4544-aee8-18a7991cad72 | AL18: 1 | AM18: 3600 | AN18: 240 | AO18: 864000 | AP18: 104.5 | AQ18: 376200 | AR18: Open | AS18: 2026-09-10 10:21 | AT18: 2026-09-10 10:21 | AU18: 88245
A19: CWL-2963 | B19: Update Phonak.de for Season 3-2026 | C19: 5 | D19: 18000 | E19: 2026-09-09 09:00 | F19: 712020:bff05832-15dc-4ee5-a497-e1c8f7ccef4b | G19: Shinde, Dakshata External | H19: Capgemini | I19: 63f8addd8ab3d6a635ee03fe | L19: 0926 | V19: Capgemini Web Localization | Z19: Task | AA19: DONE | AB19: Medium | AC19: CWL | AD19: Capgemini Web Localization | AG19: Tab 1 updated discussion with Requestor and Meciej 42 documents calling on page Navigation structure done first time to analyze it checked other nodes 4 tabs updates done QA feedback Excel status. | AI19: 712020:78e66a78-0beb-4cac-8465-d16f601ab653 | AJ19: 712020:78e66a78-0beb-4cac-8465-d16f601ab653 | AL19: 5 | AM19: 18000 | AR19: Open | AS19: 2026-09-10 11:27 | AT19: 2026-09-10 11:27 | AU19: 88254
A20: CWL-2956 | B20: Ad hoc: September | C20: 1 | D20: 3600 | E20: 2026-09-10 08:00 | F20: 712020:bff05832-15dc-4ee5-a497-e1c8f7ccef4b | G20: Shinde, Dakshata External | H20: Capgemini | I20: 63f8addd8ab3d6a635ee03fe | L20: 0926 | V20: Capgemini Web Localization | Z20: Epic | AA20: RESOLVED | AB20: Medium | AC20: CWL | AD20: Capgemini Web Localization | AE20: Ad hoc: September | AG20: Daily calls | AI20: 712020:43d154d7-2f24-4544-aee8-18a7991cad72 | AJ20: 712020:43d154d7-2f24-4544-aee8-18a7991cad72 | AL20: 1 | AM20: 3600 | AN20: 240 | AO20: 864000 | AP20: 104.5 | AQ20: 376200 | AR20: Open | AS20: 2026-09-10 10:21 | AT20: 2026-09-10 10:21 | AU20: 88244
A21: CWL-2955 | B21: Update of Support Banner Into Content Fragment | C21: 5.333 | D21: 19200 | E21: 2026-09-10 09:00 | F21: 712020:bff05832-15dc-4ee5-a497-e1c8f7ccef4b | G21: Shinde, Dakshata External | H21: Capgemini | I21: 63f8addd8ab3d6a635ee03fe | L21: 0926 | V21: Capgemini Web Localization | Z21: Task | AA21: IN PROGRESS | AB21: Medium | AC21: CWL | AD21: Capgemini Web Localization | AG21: Nl Master 112 links master and 112 links in NL Country | AI21: 613a1c0e24ba8b00701d6a93 | AJ21: 712020:3c2be4d6-9205-4a56-b7d8-1f2bb88ce234 | AL21: 5.333 | AM21: 19200 | AN21: 24 | AO21: 86400 | AP21: 0 | AQ21: 0 | AR21: Open | AS21: 2026-09-10 11:34 | AT21: 2026-09-10 11:34 | AU21: 88255
A22: CWL-2938 | B22: Please upload updated MDR DoC documents to the Phonak Certificates page and removed the older documents | C22: 1.5 | D22: 5400 | E22: 2026-09-11 08:00 | F22: 712020:bff05832-15dc-4ee5-a497-e1c8f7ccef4b | G22: Shinde, Dakshata External | H22: Capgemini | I22: 63f8addd8ab3d6a635ee03fe | L22: 0926 | V22: Capgemini Web Localization | Z22: Task | AA22: DONE | AB22: Medium | AC22: CWL | AD22: Capgemini Web Localization | AG22: Activation for all countries and live review | AI22: 6150d70078e5e40070f10fcf | AJ22: 6150d70078e5e40070f10fcf | AL22: 1.5 | AM22: 5400 | AR22: Open | AS22: 2026-09-11 14:34 | AT22: 2026-09-11 14:34 | AU22: 88339
A23: CWL-2956 | B23: Ad hoc: September | C23: 1 | D23: 3600 | E23: 2026-09-11 09:30 | F23: 712020:bff05832-15dc-4ee5-a497-e1c8f7ccef4b | G23: Shinde, Dakshata External | H23: Capgemini | I23: 63f8addd8ab3d6a635ee03fe | L23: 0926 | V23: Capgemini Web Localization | Z23: Epic | AA23: RESOLVED | AB23: Medium | AC23: CWL | AD23: Capgemini Web Localization | AE23: Ad hoc: September | AG23: Daily calls | AI23: 712020:43d154d7-2f24-4544-aee8-18a7991cad72 | AJ23: 712020:43d154d7-2f24-4544-aee8-18a7991cad72 | AL23: 1 | AM23: 3600 | AN23: 240 | AO23: 864000 | AP23: 104.5 | AQ23: 376200 | AR23: Open | AS23: 2026-09-11 14:34 | AT23: 2026-09-11 14:34 | AU23: 88340
A24: CWL-2958 | B24: Localization PH s3 - DE | C24: 5.5 | D24: 19800 | E24: 2026-09-11 10:30 | F24: 712020:bff05832-15dc-4ee5-a497-e1c8f7ccef4b | G24: Shinde, Dakshata External | H24: Capgemini | I24: 63f8addd8ab3d6a635ee03fe | L24: 0926 | V24: Capgemini Web Localization | Z24: Task | AA24: DONE | AB24: Medium | AC24: CWL | AD24: Capgemini Web Localization | AF24: PH_S3_26 | AG24: Translation and Correction received in the teams chat from requestor CH_DE Connect with Requestor | AH24: MOR-17113 | AI24: 613a1c0e24ba8b00701d6a93 | AJ24: 613a1c0e24ba8b00701d6a93 | AL24: 5.5 | AM24: 19800 | AN24: 8 | AO24: 28800 | AP24: 0 | AQ24: 0 | AR24: Open | AS24: 2026-09-11 14:37 | AT24: 2026-09-11 14:37 | AU24: 88344
A25: CWL-2970 | B25: myPhonak | C25: 3 | D25: 10800 | E25: 2026-09-21 08:00 | F25: 712020:bff05832-15dc-4ee5-a497-e1c8f7ccef4b | G25: Shinde, Dakshata External | H25: Capgemini | I25: 63f8addd8ab3d6a635ee03fe | L25: 0926 | V25: Capgemini Web Localization | Z25: Task | AA25: WAITING FOR REQUEST INFORMATION | AB25: Medium | AC25: CWL | AD25: Capgemini Web Localization | AG25: Tried several structure to create following section “myPhonak” “myPhonak Junior” “myRogerMic” Had Discussion with Requestor and DPC owner Added Videos on page | AI25: 70121:5c3aae32-8e58-44c5-8bf3-1cf71df78570 | AJ25: 70121:5c3aae32-8e58-44c5-8bf3-1cf71df78570 | AL25: 3 | AM25: 10800 | AR25: Open | AS25: 2026-09-23 07:15 | AT25: 2026-09-23 07:15 | AU25: 88811
A26: CWL-2956 | B26: Ad hoc: September | C26: 1 | D26: 3600 | E26: 2026-09-21 11:00 | F26: 712020:bff05832-15dc-4ee5-a497-e1c8f7ccef4b | G26: Shinde, Dakshata External | H26: Capgemini | I26: 63f8addd8ab3d6a635ee03fe | L26: 0926 | V26: Capgemini Web Localization | Z26: Epic | AA26: RESOLVED | AB26: Medium | AC26: CWL | AD26: Capgemini Web Localization | AE26: Ad hoc: September | AG26: Daily calls | AI26: 712020:43d154d7-2f24-4544-aee8-18a7991cad72 | AJ26: 712020:43d154d7-2f24-4544-aee8-18a7991cad72 | AL26: 1 | AM26: 3600 | AN26: 240 | AO26: 864000 | AP26: 104.5 | AQ26: 376200 | AR26: Open | AS26: 2026-09-23 07:16 | AT26: 2026-09-23 07:16 | AU26: 88812
A27: CWL-2955 | B27: Update of Support Banner Into Content Fragment | C27: 3 | D27: 10800 | E27: 2026-09-21 12:00 | F27: 712020:bff05832-15dc-4ee5-a497-e1c8f7ccef4b | G27: Shinde, Dakshata External | H27: Capgemini | I27: 63f8addd8ab3d6a635ee03fe | L27: 0926 | V27: Capgemini Web Localization | Z27: Task | AA27: IN PROGRESS | AB27: Medium | AC27: CWL | AD27: Capgemini Web Localization | AG27: NL- Links and QA feedback | AI27: 613a1c0e24ba8b00701d6a93 | AJ27: 712020:3c2be4d6-9205-4a56-b7d8-1f2bb88ce234 | AL27: 3 | AM27: 10800 | AN27: 24 | AO27: 86400 | AP27: 0 | AQ27: 0 | AR27: Open | AS27: 2026-09-23 07:19 | AT27: 2026-09-23 07:19 | AU27: 88815
A28: CWL-2970 | B28: myPhonak | C28: 1.5 | D28: 5400 | E28: 2026-09-22 08:00 | F28: 712020:bff05832-15dc-4ee5-a497-e1c8f7ccef4b | G28: Shinde, Dakshata External | H28: Capgemini | I28: 63f8addd8ab3d6a635ee03fe | L28: 0926 | V28: Capgemini Web Localization | Z28: Task | AA28: WAITING FOR REQUEST INFORMATION | AB28: Medium | AC28: CWL | AD28: Capgemini Web Localization | AG28: As discussed with requestor created navigation changes for that created the pages for “myPhonak” “myPhonak Junior” “myRogerMic” Videos added in MyPhonak page | AI28: 70121:5c3aae32-8e58-44c5-8bf3-1cf71df78570 | AJ28: 70121:5c3aae32-8e58-44c5-8bf3-1cf71df78570 | AL28: 1.5 | AM28: 5400 | AR28: Open | AS28: 2026-09-23 07:17 | AT28: 2026-09-23 07:17 | AU28: 88813
A29: CWL-2970 | B29: myPhonak | C29: 1 | D29: 3600 | E29: 2026-09-22 09:30 | F29: 712020:bff05832-15dc-4ee5-a497-e1c8f7ccef4b | G29: Shinde, Dakshata External | H29: Capgemini | I29: 63f8addd8ab3d6a635ee03fe | L29: 0926 | V29: Capgemini Web Localization | Z29: Task | AA29: WAITING FOR REQUEST INFORMATION | AB29: Medium | AC29: CWL | AD29: Capgemini Web Localization | AG29: Daily calls | AI29: 70121:5c3aae32-8e58-44c5-8bf3-1cf71df78570 | AJ29: 70121:5c3aae32-8e58-44c5-8bf3-1cf71df78570 | AL29: 1 | AM29: 3600 | AR29: Open | AS29: 2026-09-23 07:18 | AT29: 2026-09-23 07:18 | AU29: 88814
A30: CWL-2955 | B30: Update of Support Banner Into Content Fragment | C30: 2 | D30: 7200 | E30: 2026-09-22 10:30 | F30: 712020:bff05832-15dc-4ee5-a497-e1c8f7ccef4b | G30: Shinde, Dakshata External | H30: Capgemini | I30: 63f8addd8ab3d6a635ee03fe | L30: 0926 | V30: Capgemini Web Localization | Z30: Task | AA30: IN PROGRESS | AB30: Medium | AC30: CWL | AD30: Capgemini Web Localization | AG30: NL master and countries Done | AI30: 613a1c0e24ba8b00701d6a93 | AJ30: 712020:3c2be4d6-9205-4a56-b7d8-1f2bb88ce234 | AL30: 2 | AM30: 7200 | AN30: 24 | AO30: 86400 | AP30: 0 | AQ30: 0 | AR30: Open | AS30: 2026-09-23 07:19 | AT30: 2026-09-23 07:19 | AU30: 88816
A31: CWL-2956 | B31: Ad hoc: September | C31: 1 | D31: 3600 | E31: 2026-09-23 08:00 | F31: 712020:bff05832-15dc-4ee5-a497-e1c8f7ccef4b | G31: Shinde, Dakshata External | H31: Capgemini | I31: 63f8addd8ab3d6a635ee03fe | L31: 0926 | V31: Capgemini Web Localization | Z31: Epic | AA31: RESOLVED | AB31: Medium | AC31: CWL | AD31: Capgemini Web Localization | AE31: Ad hoc: September | AG31: Daily calls | AI31: 712020:43d154d7-2f24-4544-aee8-18a7991cad72 | AJ31: 712020:43d154d7-2f24-4544-aee8-18a7991cad72 | AL31: 1 | AM31: 3600 | AN31: 240 | AO31: 864000 | AP31: 104.5 | AQ31: 376200 | AR31: Open | AS31: 2026-09-25 13:39 | AT31: 2026-09-25 13:39 | AU31: 88927
A32: CWL-2955 | B32: Update of Support Banner Into Content Fragment | C32: 3 | D32: 10800 | E32: 2026-09-23 09:00 | F32: 712020:bff05832-15dc-4ee5-a497-e1c8f7ccef4b | G32: Shinde, Dakshata External | H32: Capgemini | I32: 63f8addd8ab3d6a635ee03fe | L32: 0926 | V32: Capgemini Web Localization | Z32: Task | AA32: IN PROGRESS | AB32: Medium | AC32: CWL | AD32: Capgemini Web Localization | AG32: Qa feedback, rolloutNL and activation DK | AI32: 613a1c0e24ba8b00701d6a93 | AJ32: 712020:3c2be4d6-9205-4a56-b7d8-1f2bb88ce234 | AL32: 3 | AM32: 10800 | AN32: 24 | AO32: 86400 | AP32: 0 | AQ32: 0 | AR32: Open | AS32: 2026-09-25 16:01 | AT32: 2026-09-25 16:01 | AU32: 88959
A33: CWL-2971 | B33: PH_S3 Localization SV | C33: 3 | D33: 10800 | E33: 2026-09-23 12:00 | F33: 712020:bff05832-15dc-4ee5-a497-e1c8f7ccef4b | G33: Shinde, Dakshata External | H33: Capgemini | I33: 63f8addd8ab3d6a635ee03fe | L33: 0926 | V33: Capgemini Web Localization | Z33: Task | AA33: WAITING FOR APPROVAL (MIGRATED) | AB33: Medium | AC33: CWL | AD33: Capgemini Web Localization | AF33: PH_S3_26 | AG33: CF SV master done and country 50% done | AH33: MOR-17113 | AI33: 613a1c0e24ba8b00701d6a93 | AJ33: 613a1c0e24ba8b00701d6a93 | AL33: 3 | AM33: 10800 | AN33: 12 | AO33: 43200 | AP33: 0 | AQ33: 0 | AR33: Open | AS33: 2026-09-25 16:02 | AT33: 2026-09-25 16:02 | AU33: 88960
A34: CWL-2956 | B34: Ad hoc: September | C34: 1 | D34: 3600 | E34: 2026-09-24 08:00 | F34: 712020:bff05832-15dc-4ee5-a497-e1c8f7ccef4b | G34: Shinde, Dakshata External | H34: Capgemini | I34: 63f8addd8ab3d6a635ee03fe | L34: 0926 | V34: Capgemini Web Localization | Z34: Epic | AA34: RESOLVED | AB34: Medium | AC34: CWL | AD34: Capgemini Web Localization | AE34: Ad hoc: September | AG34: Daily calls | AI34: 712020:43d154d7-2f24-4544-aee8-18a7991cad72 | AJ34: 712020:43d154d7-2f24-4544-aee8-18a7991cad72 | AL34: 1 | AM34: 3600 | AN34: 240 | AO34: 864000 | AP34: 104.5 | AQ34: 376200 | AR34: Open | AS34: 2026-09-25 13:40 | AT34: 2026-09-25 13:40 | AU34: 88928
A35: CWL-2971 | B35: PH_S3 Localization SV | C35: 6 | D35: 21600 | E35: 2026-09-24 09:00 | F35: 712020:bff05832-15dc-4ee5-a497-e1c8f7ccef4b | G35: Shinde, Dakshata External | H35: Capgemini | I35: 63f8addd8ab3d6a635ee03fe | L35: 0926 | V35: Capgemini Web Localization | Z35: Task | AA35: WAITING FOR APPROVAL (MIGRATED) | AB35: Medium | AC35: CWL | AD35: Capgemini Web Localization | AF35: PH_S3_26 | AG35: Country CF remaining done, Pages master 12 done, QA feedback implemented | AH35: MOR-17113 | AI35: 613a1c0e24ba8b00701d6a93 | AJ35: 613a1c0e24ba8b00701d6a93 | AL35: 6 | AM35: 21600 | AN35: 12 | AO35: 43200 | AP35: 0 | AQ35: 0 | AR35: Open | AS35: 2026-09-25 16:04 | AT35: 2026-09-25 16:04 | AU35: 88961
A36: CWL-2956 | B36: Ad hoc: September | C36: 1 | D36: 3600 | E36: 2026-09-25 08:00 | F36: 712020:bff05832-15dc-4ee5-a497-e1c8f7ccef4b | G36: Shinde, Dakshata External | H36: Capgemini | I36: 63f8addd8ab3d6a635ee03fe | L36: 0926 | V36: Capgemini Web Localization | Z36: Epic | AA36: RESOLVED | AB36: Medium | AC36: CWL | AD36: Capgemini Web Localization | AE36: Ad hoc: September | AG36: daily calls | AI36: 712020:43d154d7-2f24-4544-aee8-18a7991cad72 | AJ36: 712020:43d154d7-2f24-4544-aee8-18a7991cad72 | AL36: 1 | AM36: 3600 | AN36: 240 | AO36: 864000 | AP36: 104.5 | AQ36: 376200 | AR36: Open | AS36: 2026-09-25 13:40 | AT36: 2026-09-25 13:40 | AU36: 88929
A37: CWL-2971 | B37: PH_S3 Localization SV | C37: 6.5 | D37: 23400 | E37: 2026-09-25 09:00 | F37: 712020:bff05832-15dc-4ee5-a497-e1c8f7ccef4b | G37: Shinde, Dakshata External | H37: Capgemini | I37: 63f8addd8ab3d6a635ee03fe | L37: 0926 | V37: Capgemini Web Localization | Z37: Task | AA37: WAITING FOR APPROVAL (MIGRATED) | AB37: Medium | AC37: CWL | AD37: Capgemini Web Localization | AF37: PH_S3_26 | AG37: Master remaining 12 Done, Country rollout and CF, properties edits Done on 6 pages along with the QA feedback. | AH37: MOR-17113 | AI37: 613a1c0e24ba8b00701d6a93 | AJ37: 613a1c0e24ba8b00701d6a93 | AL37: 6.5 | AM37: 23400 | AN37: 12 | AO37: 43200 | AP37: 0 | AQ37: 0 | AR37: Open | AS37: 2026-09-25 16:07 | AT37: 2026-09-25 16:07 | AU37: 88962
A38: CWL-2955 | B38: Update of Support Banner Into Content Fragment | C38: 2.75 | D38: 9900 | E38: 2026-09-28 08:00 | F38: 712020:bff05832-15dc-4ee5-a497-e1c8f7ccef4b | G38: Shinde, Dakshata External | H38: Capgemini | I38: 63f8addd8ab3d6a635ee03fe | L38: 0926 | V38: Capgemini Web Localization | Z38: Task | AA38: IN PROGRESS | AB38: Medium | AC38: CWL | AD38: Capgemini Web Localization | AG38: Activation of DK two times due to activation issue, Live review | AI38: 613a1c0e24ba8b00701d6a93 | AJ38: 712020:3c2be4d6-9205-4a56-b7d8-1f2bb88ce234 | AL38: 2.75 | AM38: 9900 | AN38: 24 | AO38: 86400 | AP38: 0 | AQ38: 0 | AR38: Open | AS38: 2026-09-28 14:42 | AT38: 2026-09-28 14:42 | AU38: 89090
A39: CWL-2956 | B39: Ad hoc: September | C39: 1 | D39: 3600 | E39: 2026-09-28 10:45 | F39: 712020:bff05832-15dc-4ee5-a497-e1c8f7ccef4b | G39: Shinde, Dakshata External | H39: Capgemini | I39: 63f8addd8ab3d6a635ee03fe | L39: 0926 | V39: Capgemini Web Localization | Z39: Epic | AA39: RESOLVED | AB39: Medium | AC39: CWL | AD39: Capgemini Web Localization | AE39: Ad hoc: September | AG39: Daily calls | AI39: 712020:43d154d7-2f24-4544-aee8-18a7991cad72 | AJ39: 712020:43d154d7-2f24-4544-aee8-18a7991cad72 | AL39: 1 | AM39: 3600 | AN39: 240 | AO39: 864000 | AP39: 104.5 | AQ39: 376200 | AR39: Open | AS39: 2026-09-28 14:42 | AT39: 2026-09-28 14:42 | AU39: 89091
A40: CWL-2971 | B40: PH_S3 Localization SV | C40: 4.25 | D40: 15300 | E40: 2026-09-28 11:45 | F40: 712020:bff05832-15dc-4ee5-a497-e1c8f7ccef4b | G40: Shinde, Dakshata External | H40: Capgemini | I40: 63f8addd8ab3d6a635ee03fe | L40: 0926 | V40: Capgemini Web Localization | Z40: Task | AA40: WAITING FOR APPROVAL (MIGRATED) | AB40: Medium | AC40: CWL | AD40: Capgemini Web Localization | AF40: PH_S3_26 | AG40: SV Country level, QA feedback Done, 3 CF image path fixed | AH40: MOR-17113 | AI40: 613a1c0e24ba8b00701d6a93 | AJ40: 613a1c0e24ba8b00701d6a93 | AL40: 4.25 | AM40: 15300 | AN40: 12 | AO40: 43200 | AP40: 0 | AQ40: 0 | AR40: Open | AS40: 2026-09-28 14:48 | AT40: 2026-09-28 14:48 | AU40: 89093
...

Sheet Report
A1: Work Item | B1: Hours | C1: Minutes | D1: Work Date
A2: =IF(Worklogs!A2="","",Worklogs!A2&" "&Worklogs!B2) -> CWL-2938 Please upload updated MDR DoC documents to the Phonak Certificates page and removed the older documents | B2: =IF(Worklogs!A2="","",INT(ROUND(Worklogs!D2/60,0)/60)) -> 5 | C2: =IF(Worklogs!A2="","",MOD(ROUND(Worklogs!D2/60,0),60)) -> 20 | D2: =IF(Worklogs!A2="","",DATEVALUE(LEFT(Worklogs!E2,10))) -> 46266
A3: =IF(Worklogs!A3="","",Worklogs!A3&" "&Worklogs!B3) -> CWL-2956 Ad hoc: September | B3: =IF(Worklogs!A3="","",INT(ROUND(Worklogs!D3/60,0)/60)) -> 1 | C3: =IF(Worklogs!A3="","",MOD(ROUND(Worklogs!D3/60,0),60)) -> 0 | D3: =IF(Worklogs!A3="","",DATEVALUE(LEFT(Worklogs!E3,10))) -> 46266
A4: =IF(Worklogs!A4="","",Worklogs!A4&" "&Worklogs!B4) -> CWL-2938 Please upload updated MDR DoC documents to the Phonak Certificates page and removed the older documents | B4: =IF(Worklogs!A4="","",INT(ROUND(Worklogs!D4/60,0)/60)) -> 6 | C4: =IF(Worklogs!A4="","",MOD(ROUND(Worklogs!D4/60,0),60)) -> 30 | D4: =IF(Worklogs!A4="","",DATEVALUE(LEFT(Worklogs!E4,10))) -> 46267
A5: =IF(Worklogs!A5="","",Worklogs!A5&" "&Worklogs!B5) -> CWL-2956 Ad hoc: September | B5: =IF(Worklogs!A5="","",INT(ROUND(Worklogs!D5/60,0)/60)) -> 1 | C5: =IF(Worklogs!A5="","",MOD(ROUND(Worklogs!D5/60,0),60)) -> 0 | D5: =IF(Worklogs!A5="","",DATEVALUE(LEFT(Worklogs!E5,10))) -> 46267
A6: =IF(Worklogs!A6="","",Worklogs!A6&" "&Worklogs!B6) -> CWL-2926 Brazil Hansaton Website Update - User Guides | B6: =IF(Worklogs!A6="","",INT(ROUND(Worklogs!D6/60,0)/60)) -> 0 | C6: =IF(Worklogs!A6="","",MOD(ROUND(Worklogs!D6/60,0),60)) -> 10 | D6: =IF(Worklogs!A6="","",DATEVALUE(LEFT(Worklogs!E6,10))) -> 46268
A7: =IF(Worklogs!A7="","",Worklogs!A7&" "&Worklogs!B7) -> CWL-2943 HT_Website_Software Update Download Center 5.10.1 | B7: =IF(Worklogs!A7="","",INT(ROUND(Worklogs!D7/60,0)/60)) -> 0 | C7: =IF(Worklogs!A7="","",MOD(ROUND(Worklogs!D7/60,0),60)) -> 20 | D7: =IF(Worklogs!A7="","",DATEVALUE(LEFT(Worklogs!E7,10))) -> 46268
A8: =IF(Worklogs!A8="","",Worklogs!A8&" "&Worklogs!B8) -> CWL-2942 HT_Website_Download Center Spain | B8: =IF(Worklogs!A8="","",INT(ROUND(Worklogs!D8/60,0)/60)) -> 0 | C8: =IF(Worklogs!A8="","",MOD(ROUND(Worklogs!D8/60,0),60)) -> 10 | D8: =IF(Worklogs!A8="","",DATEVALUE(LEFT(Worklogs!E8,10))) -> 46268
A9: =IF(Worklogs!A9="","",Worklogs!A9&" "&Worklogs!B9) -> CWL-2956 Ad hoc: September | B9: =IF(Worklogs!A9="","",INT(ROUND(Worklogs!D9/60,0)/60)) -> 1 | C9: =IF(Worklogs!A9="","",MOD(ROUND(Worklogs!D9/60,0),60)) -> 0 | D9: =IF(Worklogs!A9="","",DATEVALUE(LEFT(Worklogs!E9,10))) -> 46268
A10: =IF(Worklogs!A10="","",Worklogs!A10&" "&Worklogs!B10) -> CWL-2938 Please upload updated MDR DoC documents to the Phonak Certificates page and removed the older documents | B10: =IF(Worklogs!A10="","",INT(ROUND(Worklogs!D10/60,0)/60)) -> 0 | C10: =IF(Worklogs!A10="","",MOD(ROUND(Worklogs!D10/60,0),60)) -> 20 | D10: =IF(Worklogs!A10="","",DATEVALUE(LEFT(Worklogs!E10,10))) -> 46268
A11: =IF(Worklogs!A11="","",Worklogs!A11&" "&Worklogs!B11) -> CWL-2958 Localization PH s3 - DE | B11: =IF(Worklogs!A11="","",INT(ROUND(Worklogs!D11/60,0)/60)) -> 6 | C11: =IF(Worklogs!A11="","",MOD(ROUND(Worklogs!D11/60,0),60)) -> 0 | D11: =IF(Worklogs!A11="","",DATEVALUE(LEFT(Worklogs!E11,10))) -> 46268
A12: =IF(Worklogs!A12="","",Worklogs!A12&" "&Worklogs!B12) -> CWL-2956 Ad hoc: September | B12: =IF(Worklogs!A12="","",INT(ROUND(Worklogs!D12/60,0)/60)) -> 1 | C12: =IF(Worklogs!A12="","",MOD(ROUND(Worklogs!D12/60,0),60)) -> 0 | D12: =IF(Worklogs!A12="","",DATEVALUE(LEFT(Worklogs!E12,10))) -> 46269
A13: =IF(Worklogs!A13="","",Worklogs!A13&" "&Worklogs!B13) -> CWL-2958 Localization PH s3 - DE | B13: =IF(Worklogs!A13="","",INT(ROUND(Worklogs!D13/60,0)/60)) -> 6 | C13: =IF(Worklogs!A13="","",MOD(ROUND(Worklogs!D13/60,0),60)) -> 48 | D13: =IF(Worklogs!A13="","",DATEVALUE(LEFT(Worklogs!E13,10))) -> 46269
... A301: =IF(Worklogs!A301="","",Worklogs!A301&" "&Worklogs!B301) | B301: =IF(Worklogs!A301="","",INT(ROUND(Worklogs!D301/60,0)/60)) | C301: =IF(Worklogs!A301="","",MOD(ROUND(Worklogs!D301/60,0),60)) | D301: =IF(Worklogs!A301="","",DATEVALUE(LEFT(Worklogs!E301,10)))

Sheet Users
A1: Full name | B1: User Account ID | C1: Logged Hours | D1: Logged Seconds | E1: Billable Hours | F1: Billable Seconds | G1: Planned Hours | H1: Planned Seconds | I1: Required Hours | J1: Required Seconds | K1: Progress | L1: Period | M1: 2026-09-01 | N1: 2026-09-02 | O1: 2026-09-03 | P1: 2026-09-04 | Q1: 2026-09-05 | R1: 2026-09-06 | S1: 2026-09-07 | T1: 2026-09-08 | U1: 2026-09-09 | V1: 2026-09-10 | W1: 2026-09-11 | X1: 2026-09-12 | Y1: 2026-09-13 | Z1: 2026-09-14 | AA1: 2026-09-15 | AB1: 2026-09-16 | AC1: 2026-09-17 | AD1: 2026-09-18 | AE1: 2026-09-19 | AF1: 2026-09-20 | AG1: 2026-09-21 | AH1: 2026-09-22 | AI1: 2026-09-23 | AJ1: 2026-09-24 | AK1: 2026-09-25 | AL1: 2026-09-26 | AM1: 2026-09-27 | AN1: 2026-09-28 | AO1: 2026-09-29 | AP1: 2026-09-30
A2: Shinde, Dakshata External | B2: 712020:bff05832-15dc-4ee5-a497-e1c8f7ccef4b | C2: 117.133 | D2: 421680 | E2: 117.133 | F2: 421680 | G2: 0 | H2: 0 | I2: 176 | J2: 633600 | K2: 67 | L2: Ready to submit | M2: 6.333 | N2: 7.5 | O2: 8 | P2: 7.8 | Q2: 0 | R2: 0 | S2: 6 | T2: 6.167 | U2: 6 | V2: 6.333 | W2: 8 | X2: 0 | Y2: 0 | Z2: 0 | AA2: 0 | AB2: 0 | AC2: 0 | AD2: 0 | AE2: 0 | AF2: 0 | AG2: 7 | AH2: 4.5 | AI2: 7 | AJ2: 7 | AK2: 7.5 | AL2: 0 | AM2: 0 | AN2: 8 | AO2: 7 | AP2: 7
